Workbook
Name AvgDays: SUMPRODUCT(Marketing!$A$2:$A$9,Marketing!$B$2:$B$9)/100
Name BarnDays: Inputs!$C$54
Name BarnDowntime: Inputs!$C$28
Name BarnMode: Inputs!$C$27
Name BarnPerPig: Inputs!$C$29
Name BarnRent: Inputs!$C$48
Name BasisByPeriod: 'Market Data'!$F$3:$F$26
Name CarcassCwt: SUMPRODUCT(Marketing!$K$2:$K$9,Marketing!$L$2:$L$9)/100
Name CheckoffCost: Costs!$B$11
Name CheckoffPct: Inputs!$C$41
Name CornBasis: Inputs!$C$45
Name CornCash: Inputs!$C$50
Name CornFutures: Inputs!$C$22
Name DdgsPrice: Inputs!$C$47
Name DeadFeedShare: Inputs!$C$10
Name FeedCost: Feed!$M$14
Name FeedMill: Inputs!$C$24
Name FeedTons: Feed!$H$14
Name FutContracts: 'Market Data'!$A$3:$A$26
Name FutPrices: 'Market Data'!$B$3:$B$26
Name GrossRevenue: Marketing!$M$10
Name HeadPlaced: Inputs!$C$6
Name HeadSold: Inputs!$C$53
Name InsMisc: Inputs!$C$36
Name InterestPct: Inputs!$C$37
Name LaborHours: Inputs!$C$31
Name LaborMode: Inputs!$C$30
Name LaborPerPig: Inputs!$C$32
Name LaborWage: Inputs!$C$49
Name LiveCwt: SUMPRODUCT(Marketing!$K$2:$K$9,Marketing!$C$2:$C$9)/100
Name Location: Inputs!$C$12
Name LocRow: Inputs!$C$44
Name MortalityPct: Inputs!$C$9
Name PigsFed: Inputs!$C$55
Name PlacementDate: Inputs!$C$7
Name Premium: Inputs!$C$40
Name SbmBasis: Inputs!$C$46
Name SbmCash: Inputs!$C$51
Name SbmFutures: Inputs!$C$23
Name TotalCost: Costs!$B$12
Name Trucking: Inputs!$C$35
Name Utilities: Inputs!$C$34
Name VetMed: Inputs!$C$33
Name WeanCash: Inputs!$C$16
Name WeanFormula: Inputs!$C$17
Name WeanFreight: Inputs!$C$19
Name WeanManual: Inputs!$C$18
Name WeanPrice: Inputs!$C$52
Name WeanSource: Inputs!$C$15
Name WeanWeight: Inputs!$C$8
Name YieldPct: Inputs!$C$11

Sheet Dashboard
B1: Wean-to-Finish Group Projection
B2: ="Location: "&Location&" | Placed: "&TEXT(PlacementDate,"mmm d, yyyy")&" | Head placed: "&TEXT(HeadPlaced,"#,##0") -> 0
B4: Net profit (group) | C4: =GrossRevenue-TotalCost -> 0 | E4: Breakeven $/cwt carcass | F4: =(TotalCost-CheckoffCost)/(CarcassCwt*(1-CheckoffPct/100)) -> 0
B5: Net $/head sold | C5: =(GrossRevenue-TotalCost)/HeadSold -> 0 | E5: Breakeven $/cwt live | F5: =F4*YieldPct/100 -> 0
B6: Total revenue | C6: =GrossRevenue -> 0 | E6: Avg sale price $/cwt carcass | F6: =GrossRevenue/CarcassCwt -> 0
B7: Total cost | C7: =TotalCost -> 0 | E7: Cost $/cwt carcass | F7: =TotalCost/CarcassCwt -> 0
B8: Revenue $/head sold | C8: =GrossRevenue/HeadSold -> 0 | E8: Head sold | F8: =HeadSold -> 0
B9: Cost $/head sold | C9: =TotalCost/HeadSold -> 0 | E9: Feed conversion (lb feed / lb gain) | F9: =IF(LiveCwt*100-HeadPlaced*WeanWeight<=0,"n/a",FeedTons*2000/(LiveCwt*100-HeadPlaced*WeanWeight)) -> 0
B11: Key prices
B12: Corn cash $/bu (futures + basis) | C12: =CornCash -> 0
B13: Corn basis $/bu | C13: =CornBasis -> 0
B14: Soybean meal cash $/ton | C14: =SbmCash -> 0
B15: Soybean meal basis $/ton | C15: =SbmBasis -> 0
B16: DDGS $/ton | C16: =DdgsPrice -> 0
B17: Weaned pig $/head | C17: =WeanPrice -> 0

Sheet Inputs
B1: Inputs — yellow cells are editable
B2: Change any yellow cell; every other sheet recalculates.
B5: Group
B6: Head placed | C6: 2400 | D6: head
B7: Placement date | C7: 46314 | D7: date
B8: Weaned pig weight | C8: 12 | D8: lb
B9: Mortality (wean to market) | C9: 6.8 | D9: %
B10: Feed eaten by a dead pig (share of full budget) | C10: 0.25 | D10: 0-1 | E10: Most death loss is early, so deads eat little
B11: Carcass yield | C11: 75 | D11: % | E11: Hot carcass / live
B12: Feeding location | C12: Northwest Iowa | E12: Pick from list; prices come from the Locations sheet
B14: Weaned pig
B15: Weaned pig price source | C15: USDA cash (open market) | E15: USDA cash = open market; 2,400+ head lots if reported, else the largest lot
B16: USDA weaned pig cash price | C16: 24.81 | D16: $/head | E16: USDA AMS National Direct Feeder Pig Report (weekly, report 2810), early weaned
B17: USDA weaned pig formula price | C17: 24.81 | D17: $/head | E17: Same report, formula purchases
B18: Manual weaned pig price | C18: 24.81 | D18: $/head
B19: Weaned pig freight | C19: 1 | D19: $/head
B21: Feed prices
B22: CBOT corn futures | C22: 4.7425 | D22: $/bu
B23: CBOT soybean meal futures | C23: 357.1 | D23: $/ton
B24: Feed mill grind/mix/delivery | C24: 15 | D24: $/ton
B26: Barn, labor and other
B27: Barn cost method | C27: $/space/year
B28: Barn downtime between groups | C28: 10 | D28: days | E28: Wash/dry/fill. Barn days = last marketing day + downtime
B29: Barn cost if $/pig placed | C29: 0 | D29: $/pig
B30: Labor cost method | C30: hours x wage
B31: Labor hours per pig placed | C31: 0.2 | D31: hr/pig | E31: Wage comes from the Locations sheet
B32: Labor cost if $/pig placed | C32: 0 | D32: $/pig
B33: Vet / med / vaccine | C33: 5 | D33: $/head placed
B34: Utilities / fuel | C34: 4 | D34: $/head placed
B35: Trucking to market | C35: 4 | D35: $/head sold
B36: Insurance / misc | C36: 0.5 | D36: $/head placed
B37: Operating interest rate | C37: 7.12 | D37: %/yr | E37: On pig cost + half of feed, for the feeding period
B39: Revenue
B40: Carcass merit premium | C40: 1.5 | D40: $/cwt carcass
B41: Pork checkoff | C41: 0.35 | D41: % of gross
B43: From selected location (edit on Locations sheet)
B44: Location row | C44: =MATCH(Location,Locations!$A$2:$A$61,0) -> 0
B45: Corn basis | C45: =INDEX(Locations!$C$2:$C$61,LocRow) -> 0
B46: Soybean meal basis | C46: =INDEX(Locations!$D$2:$D$61,LocRow) -> 0
B47: DDGS price | C47: =INDEX(Locations!$E$2:$E$61,LocRow) -> 0
...

Sheet Locations
A1: Location | B1: State | C1: Corn basis $/bu | D1: SBM basis $/ton | E1: DDGS $/ton | F1: Barn rent $/space/yr | G1: Labor wage $/hr | H1: Source / notes
A2: Central Illinois | B2: IL | C2: -0.3 | D2: 38 | E2: 200 | F2: 40 | G2: 18.15 | H2: IL SBM FOB avg $378.06 (AMS 3668 Oct 8 2026) +$20 truck. DDGS: AMS 3618 IL $202.50 (Oct 5 2026). Basis [ESTIMATE]
A3: Central Indiana | B3: IN | C3: -0.3 | D3: 35 | E3: 188 | F3: 40 | G3: 18.15 | H3: SBM: Bunge Decatur IN +$10-20 over Dec ZM (Oct 17 2026) +$20 truck. DDGS: AMS 3618 IN $187.88 (Oct 5 2026). Basis [ESTIMATE]
A4: Central Iowa | B4: IA | C4: -0.35 | D4: 30 | E4: 178 | F4: 40 | G4: 18.15 | H4: Processor demand near Des Moines [ESTIMATE]. DDGS: AMS 3618 IA (Oct 5 2026). Barn/wage [VERIFY]
A5: Central South Dakota | B5: SD | C5: -0.7 | D5: 35 | E5: 195 | F5: 40 | G5: 17.51 | H5: Corn basis: far from processors/rail [ESTIMATE]. SBM: +15 FOB +$20 truck [ESTIMATE]. DDGS: AMS 3618 SD $195.00 (Oct 5 2026). Barn [VERIFY]. Wage: NASS Northern Plains $17.51 (Oct 2024) [VERIFY]
A6: Eastern South Dakota (Sioux Falls) | B6: SD | C6: -0.5 | D6: 30 | E6: 195 | F6: 40 | G6: 17.51 | H6: [ESTIMATE] basis. DDGS: AMS 3618 SD (Oct 5 2026). Wage: NASS Northern Plains (Oct 2024) [VERIFY]
A7: Northeast Iowa | B7: IA | C7: -0.45 | D7: 32 | E7: 180 | F7: 40 | G7: 18.15 | H7: Corn basis weaker than NW IA in Aug 2026 AMS 2850 [ESTIMATE]. DDGS: AMS 3618 IA (Oct 5 2026). Barn/wage [VERIFY]
A8: Northeast Nebraska | B8: NE | C8: -0.35 | D8: 32 | E8: 205 | F8: 40 | G8: 17.51 | H8: NE cash $4.27-5.18 (Oct 13 2026) [ESTIMATE]. DDGS: AMS 3618 NE $207.50 (Oct 5 2026). Wage: NASS Northern Plains [VERIFY]
A9: Northern Missouri | B9: MO | C9: -0.5 | D9: 40 | E9: 195 | F9: 40 | G9: 18.15 | H9: No MO DDGS series found; all values [ESTIMATE]
A10: Northwest Iowa | B10: IA | C10: -0.4 | D10: 30 | E10: 180 | F10: 40 | G10: 18.15 | H10: Corn basis: NW IA co-op Dec bids -37/-39 (Oct 7 2026) [ESTIMATE]. SBM: IA FOB avg $366.75 (AMS 3668 Oct 8 2026) = ~+10 over Dec ZM, +$20 truck to farm [ESTIMATE]. DDGS: AMS 3618 IA $179.79 (Oct 5 2026). Barn: $30-40/space/yr extension range, rising build cost [VERIFY]. Wage: NASS US livestock $18.15 (Apr 2025) [VERIFY regional]
A11: Southern Minnesota | B11: MN | C11: -0.5 | D11: 25 | E11: 186 | F11: 40 | G11: 18.15 | H11: S. MN cash $4.18-4.36 (Oct 13 2026) [ESTIMATE]. DDGS: AMS 3618 MN (Oct 5 2026). Barn/wage [VERIFY]
A12: Southwest Iowa | B12: IA | C12: -0.38 | D12: 32 | E12: 182 | F12: 40 | G12: 18.15 | H12: Council Bluffs processors [ESTIMATE]. DDGS: AMS 3618 IA (Oct 5 2026). Barn/wage [VERIFY]
A13: Southwest Minnesota | B13: MN | C13: -0.5 | D13: 25 | E13: 186 | F13: 40 | G13: 18.15 | H13: Corn basis: S. MN cash $4.18-4.36 (Oct 13 2026) vs Dec [ESTIMATE]. SBM: MN FOB avg $359.79 (AMS 3668 Oct 8 2026) +$20 truck [ESTIMATE]. DDGS: AMS 3618 MN $186.25 (Oct 5 2026). Barn [VERIFY]. Wage: NASS US $18.15 [VERIFY regional]
A63: Add a location in any empty yellow row; it appears in the Inputs location dropdown.

Sheet Feed
A1: Phase | B1: Feed lb/pig | C1: Corn % | D1: SBM % | E1: DDGS % | F1: Other % | G1: Other $/ton | H1: Tons | I1: Corn bu | J1: SBM tons | K1: DDGS tons | L1: Other tons | M1: Cost $ | N1: $/ton
A2: Nursery 1 (12-25 lb) | B2: 20 | C2: 45 | D2: 22 | E2: 0 | F2: =IF(B2="",0,MAX(0,100-C2-D2-E2)) -> 0 | G2: 1600 | H2: =N(B2)*PigsFed/2000 -> 0 | I2: =H2*2000*N(C2)/100/56 -> 0 | J2: =H2*N(D2)/100 -> 0 | K2: =H2*N(E2)/100 -> 0 | L2: =H2*F2/100 -> 0 | M2: =I2*CornCash+J2*SbmCash+K2*DdgsPrice+L2*N(G2)+H2*FeedMill -> 0 | N2: =IF(H2=0,0,M2/H2) -> 0
A3: Nursery 2 (25-50 lb) | B3: 35 | C3: 58 | D3: 25 | E3: 10 | F3: =IF(B3="",0,MAX(0,100-C3-D3-E3)) -> 0 | G3: 1000 | H3: =N(B3)*PigsFed/2000 -> 0 | I3: =H3*2000*N(C3)/100/56 -> 0 | J3: =H3*N(D3)/100 -> 0 | K3: =H3*N(E3)/100 -> 0 | L3: =H3*F3/100 -> 0 | M3: =I3*CornCash+J3*SbmCash+K3*DdgsPrice+L3*N(G3)+H3*FeedMill -> 0 | N3: =IF(H3=0,0,M3/H3) -> 0
A4: Grower 1 (50-100 lb) | B4: 120 | C4: 58 | D4: 20 | E4: 20 | F4: =IF(B4="",0,MAX(0,100-C4-D4-E4)) -> 0 | G4: 1200 | H4: =N(B4)*PigsFed/2000 -> 0 | I4: =H4*2000*N(C4)/100/56 -> 0 | J4: =H4*N(D4)/100 -> 0 | K4: =H4*N(E4)/100 -> 0 | L4: =H4*F4/100 -> 0 | M4: =I4*CornCash+J4*SbmCash+K4*DdgsPrice+L4*N(G4)+H4*FeedMill -> 0 | N4: =IF(H4=0,0,M4/H4) -> 0
A5: Grower 2 (100-160 lb) | B5: 160 | C5: 63 | D5: 14 | E5: 20 | F5: =IF(B5="",0,MAX(0,100-C5-D5-E5)) -> 0 | G5: 1200 | H5: =N(B5)*PigsFed/2000 -> 0 | I5: =H5*2000*N(C5)/100/56 -> 0 | J5: =H5*N(D5)/100 -> 0 | K5: =H5*N(E5)/100 -> 0 | L5: =H5*F5/100 -> 0 | M5: =I5*CornCash+J5*SbmCash+K5*DdgsPrice+L5*N(G5)+H5*FeedMill -> 0 | N5: =IF(H5=0,0,M5/H5) -> 0
A6: Finisher 1 (160-220 lb) | B6: 180 | C6: 67 | D6: 10 | E6: 20 | F6: =IF(B6="",0,MAX(0,100-C6-D6-E6)) -> 0 | G6: 1200 | H6: =N(B6)*PigsFed/2000 -> 0 | I6: =H6*2000*N(C6)/100/56 -> 0 | J6: =H6*N(D6)/100 -> 0 | K6: =H6*N(E6)/100 -> 0 | L6: =H6*F6/100 -> 0 | M6: =I6*CornCash+J6*SbmCash+K6*DdgsPrice+L6*N(G6)+H6*FeedMill -> 0 | N6: =IF(H6=0,0,M6/H6) -> 0
A7: Finisher 2 (220-285 lb) | B7: 195 | C7: 74 | D7: 8 | E7: 15 | F7: =IF(B7="",0,MAX(0,100-C7-D7-E7)) -> 0 | G7: 1200 | H7: =N(B7)*PigsFed/2000 -> 0 | I7: =H7*2000*N(C7)/100/56 -> 0 | J7: =H7*N(D7)/100 -> 0 | K7: =H7*N(E7)/100 -> 0 | L7: =H7*F7/100 -> 0 | M7: =I7*CornCash+J7*SbmCash+K7*DdgsPrice+L7*N(G7)+H7*FeedMill -> 0 | N7: =IF(H7=0,0,M7/H7) -> 0
F8: =IF(B8="",0,MAX(0,100-C8-D8-E8)) -> 0 | H8: =N(B8)*PigsFed/2000 -> 0 | I8: =H8*2000*N(C8)/100/56 -> 0 | J8: =H8*N(D8)/100 -> 0 | K8: =H8*N(E8)/100 -> 0 | L8: =H8*F8/100 -> 0 | M8: =I8*CornCash+J8*SbmCash+K8*DdgsPrice+L8*N(G8)+H8*FeedMill -> 0 | N8: =IF(H8=0,0,M8/H8) -> 0
F9: =IF(B9="",0,MAX(0,100-C9-D9-E9)) -> 0 | H9: =N(B9)*PigsFed/2000 -> 0 | I9: =H9*2000*N(C9)/100/56 -> 0 | J9: =H9*N(D9)/100 -> 0 | K9: =H9*N(E9)/100 -> 0 | L9: =H9*F9/100 -> 0 | M9: =I9*CornCash+J9*SbmCash+K9*DdgsPrice+L9*N(G9)+H9*FeedMill -> 0 | N9: =IF(H9=0,0,M9/H9) -> 0
F10: =IF(B10="",0,MAX(0,100-C10-D10-E10)) -> 0 | H10: =N(B10)*PigsFed/2000 -> 0 | I10: =H10*2000*N(C10)/100/56 -> 0 | J10: =H10*N(D10)/100 -> 0 | K10: =H10*N(E10)/100 -> 0 | L10: =H10*F10/100 -> 0 | M10: =I10*CornCash+J10*SbmCash+K10*DdgsPrice+L10*N(G10)+H10*FeedMill -> 0 | N10: =IF(H10=0,0,M10/H10) -> 0
F11: =IF(B11="",0,MAX(0,100-C11-D11-E11)) -> 0 | H11: =N(B11)*PigsFed/2000 -> 0 | I11: =H11*2000*N(C11)/100/56 -> 0 | J11: =H11*N(D11)/100 -> 0 | K11: =H11*N(E11)/100 -> 0 | L11: =H11*F11/100 -> 0 | M11: =I11*CornCash+J11*SbmCash+K11*DdgsPrice+L11*N(G11)+H11*FeedMill -> 0 | N11: =IF(H11=0,0,M11/H11) -> 0
F12: =IF(B12="",0,MAX(0,100-C12-D12-E12)) -> 0 | H12: =N(B12)*PigsFed/2000 -> 0 | I12: =H12*2000*N(C12)/100/56 -> 0 | J12: =H12*N(D12)/100 -> 0 | K12: =H12*N(E12)/100 -> 0 | L12: =H12*F12/100 -> 0 | M12: =I12*CornCash+J12*SbmCash+K12*DdgsPrice+L12*N(G12)+H12*FeedMill -> 0 | N12: =IF(H12=0,0,M12/H12) -> 0
F13: =IF(B13="",0,MAX(0,100-C13-D13-E13)) -> 0 | H13: =N(B13)*PigsFed/2000 -> 0 | I13: =H13*2000*N(C13)/100/56 -> 0 | J13: =H13*N(D13)/100 -> 0 | K13: =H13*N(E13)/100 -> 0 | L13: =H13*F13/100 -> 0 | M13: =I13*CornCash+J13*SbmCash+K13*DdgsPrice+L13*N(G13)+H13*FeedMill -> 0 | N13: =IF(H13=0,0,M13/H13) -> 0
A14: Total | B14: =SUM(B2:B13) -> 0 | H14: =SUM(H2:H13) -> 0 | I14: =SUM(I2:I13) -> 0 | J14: =SUM(J2:J13) -> 0 | K14: =SUM(K2:K13) -> 0 | L14: =SUM(L2:L13) -> 0 | M14: =SUM(M2:M13) -> 0 | N14: =IF(H14=0,0,M14/H14) -> 0
A16: Other % = premix, fat, amino acids, minerals; priced by the Other $/ton column. Feed lb/pig is per pig marketed.

Sheet Marketing
A1: Days after placement | B1: % of marketed | C1: Live wt lb | D1: Sale date | E1: Contract | F1: Basis period | G1: Futures $/cwt | H1: Basis $/cwt | I1: Premium $/cwt | J1: Price $/cwt carcass | K1: Head | L1: Carcass lb | M1: Revenue $
A2: 145 | B2: 20 | C2: 270 | D2: =IF(A2<>"",PlacementDate+A2,"") -> 0 | E2: =IF(A2<>"",(YEAR(D2)+(IF(AND(ISNUMBER(MATCH(MONTH(D2),{2,4,5,6,7,8,10,12},0)),DAY(D2)<=14),MONTH(D2),IF(MONTH(D2)<2,2,IF(MONTH(D2)<4,4,IF(MONTH(D2)<8,MONTH(D2)+1,IF(MONTH(D2)<10,10,IF(MONTH(D2)<12,12,14))))))>12))&"-"&TEXT(IF(AND(ISNUMBER(MATCH(MONTH(D2),{2,4,5,6,7,8,10,12},0)),DAY(D2)<=14),MONTH(D2),IF(MONTH(D2)<2,2,IF(MONTH(D2)<4,4,IF(MONTH(D2)<8,MONTH(D2)+1,IF(MONTH(D2)<10,10,IF(MONTH(D2)<12,12,14))))))-12*(IF(AND(ISNUMBER(MATCH(MONTH(D2),{2,4,5,6,7,8,10,12},0)),DAY(D2)<=14),MONTH(D2),IF(MONTH(D2)<2,2,IF(MONTH(D2)<4,4,IF(MONTH(D2)<8,MONTH(D2)+1,IF(MONTH(D2)<10,10,IF(MONTH(D2)<12,12,14))))))>12),"00"),"") -> 0 | F2: =IF(A2<>"",(MONTH(D2)-1)*2+IF(DAY(D2)<=14,1,2),0) -> 0 | G2: =IF(AND(A2<>"",N(B2)>0),INDEX(FutPrices,MATCH(E2,FutContracts,0)),0) -> 0 | H2: =IF(AND(A2<>"",N(B2)>0),INDEX(BasisByPeriod,F2),0) -> 0 | I2: =IF(AND(A2<>"",N(B2)>0),Premium,0) -> 0 | J2: =G2+H2+I2 -> 0 | K2: =HeadSold*N(B2)/100 -> 0 | L2: =N(C2)*YieldPct/100 -> 0 | M2: =K2*L2/100*J2 -> 0
A3: 160 | B3: 40 | C3: 285 | D3: =IF(A3<>"",PlacementDate+A3,"") -> 0 | E3: =IF(A3<>"",(YEAR(D3)+(IF(AND(ISNUMBER(MATCH(MONTH(D3),{2,4,5,6,7,8,10,12},0)),DAY(D3)<=14),MONTH(D3),IF(MONTH(D3)<2,2,IF(MONTH(D3)<4,4,IF(MONTH(D3)<8,MONTH(D3)+1,IF(MONTH(D3)<10,10,IF(MONTH(D3)<12,12,14))))))>12))&"-"&TEXT(IF(AND(ISNUMBER(MATCH(MONTH(D3),{2,4,5,6,7,8,10,12},0)),DAY(D3)<=14),MONTH(D3),IF(MONTH(D3)<2,2,IF(MONTH(D3)<4,4,IF(MONTH(D3)<8,MONTH(D3)+1,IF(MONTH(D3)<10,10,IF(MONTH(D3)<12,12,14))))))-12*(IF(AND(ISNUMBER(MATCH(MONTH(D3),{2,4,5,6,7,8,10,12},0)),DAY(D3)<=14),MONTH(D3),IF(MONTH(D3)<2,2,IF(MONTH(D3)<4,4,IF(MONTH(D3)<8,MONTH(D3)+1,IF(MONTH(D3)<10,10,IF(MONTH(D3)<12,12,14))))))>12),"00"),"") -> 0 | F3: =IF(A3<>"",(MONTH(D3)-1)*2+IF(DAY(D3)<=14,1,2),0) -> 0 | G3: =IF(AND(A3<>"",N(B3)>0),INDEX(FutPrices,MATCH(E3,FutContracts,0)),0) -> 0 | H3: =IF(AND(A3<>"",N(B3)>0),INDEX(BasisByPeriod,F3),0) -> 0 | I3: =IF(AND(A3<>"",N(B3)>0),Premium,0) -> 0 | J3: =G3+H3+I3 -> 0 | K3: =HeadSold*N(B3)/100 -> 0 | L3: =N(C3)*YieldPct/100 -> 0 | M3: =K3*L3/100*J3 -> 0
A4: 175 | B4: 40 | C4: 290 | D4: =IF(A4<>"",PlacementDate+A4,"") -> 0 | E4: =IF(A4<>"",(YEAR(D4)+(IF(AND(ISNUMBER(MATCH(MONTH(D4),{2,4,5,6,7,8,10,12},0)),DAY(D4)<=14),MONTH(D4),IF(MONTH(D4)<2,2,IF(MONTH(D4)<4,4,IF(MONTH(D4)<8,MONTH(D4)+1,IF(MONTH(D4)<10,10,IF(MONTH(D4)<12,12,14))))))>12))&"-"&TEXT(IF(AND(ISNUMBER(MATCH(MONTH(D4),{2,4,5,6,7,8,10,12},0)),DAY(D4)<=14),MONTH(D4),IF(MONTH(D4)<2,2,IF(MONTH(D4)<4,4,IF(MONTH(D4)<8,MONTH(D4)+1,IF(MONTH(D4)<10,10,IF(MONTH(D4)<12,12,14))))))-12*(IF(AND(ISNUMBER(MATCH(MONTH(D4),{2,4,5,6,7,8,10,12},0)),DAY(D4)<=14),MONTH(D4),IF(MONTH(D4)<2,2,IF(MONTH(D4)<4,4,IF(MONTH(D4)<8,MONTH(D4)+1,IF(MONTH(D4)<10,10,IF(MONTH(D4)<12,12,14))))))>12),"00"),"") -> 0 | F4: =IF(A4<>"",(MONTH(D4)-1)*2+IF(DAY(D4)<=14,1,2),0) -> 0 | G4: =IF(AND(A4<>"",N(B4)>0),INDEX(FutPrices,MATCH(E4,FutContracts,0)),0) -> 0 | H4: =IF(AND(A4<>"",N(B4)>0),INDEX(BasisByPeriod,F4),0) -> 0 | I4: =IF(AND(A4<>"",N(B4)>0),Premium,0) -> 0 | J4: =G4+H4+I4 -> 0 | K4: =HeadSold*N(B4)/100 -> 0 | L4: =N(C4)*YieldPct/100 -> 0 | M4: =K4*L4/100*J4 -> 0
D5: =IF(A5<>"",PlacementDate+A5,"") -> 0 | E5: =IF(A5<>"",(YEAR(D5)+(IF(AND(ISNUMBER(MATCH(MONTH(D5),{2,4,5,6,7,8,10,12},0)),DAY(D5)<=14),MONTH(D5),IF(MONTH(D5)<2,2,IF(MONTH(D5)<4,4,IF(MONTH(D5)<8,MONTH(D5)+1,IF(MONTH(D5)<10,10,IF(MONTH(D5)<12,12,14))))))>12))&"-"&TEXT(IF(AND(ISNUMBER(MATCH(MONTH(D5),{2,4,5,6,7,8,10,12},0)),DAY(D5)<=14),MONTH(D5),IF(MONTH(D5)<2,2,IF(MONTH(D5)<4,4,IF(MONTH(D5)<8,MONTH(D5)+1,IF(MONTH(D5)<10,10,IF(MONTH(D5)<12,12,14))))))-12*(IF(AND(ISNUMBER(MATCH(MONTH(D5),{2,4,5,6,7,8,10,12},0)),DAY(D5)<=14),MONTH(D5),IF(MONTH(D5)<2,2,IF(MONTH(D5)<4,4,IF(MONTH(D5)<8,MONTH(D5)+1,IF(MONTH(D5)<10,10,IF(MONTH(D5)<12,12,14))))))>12),"00"),"") -> 0 | F5: =IF(A5<>"",(MONTH(D5)-1)*2+IF(DAY(D5)<=14,1,2),0) -> 0 | G5: =IF(AND(A5<>"",N(B5)>0),INDEX(FutPrices,MATCH(E5,FutContracts,0)),0) -> 0 | H5: =IF(AND(A5<>"",N(B5)>0),INDEX(BasisByPeriod,F5),0) -> 0 | I5: =IF(AND(A5<>"",N(B5)>0),Premium,0) -> 0 | J5: =G5+H5+I5 -> 0 | K5: =HeadSold*N(B5)/100 -> 0 | L5: =N(C5)*YieldPct/100 -> 0 | M5: =K5*L5/100*J5 -> 0
D6: =IF(A6<>"",PlacementDate+A6,"") -> 0 | E6: =IF(A6<>"",(YEAR(D6)+(IF(AND(ISNUMBER(MATCH(MONTH(D6),{2,4,5,6,7,8,10,12},0)),DAY(D6)<=14),MONTH(D6),IF(MONTH(D6)<2,2,IF(MONTH(D6)<4,4,IF(MONTH(D6)<8,MONTH(D6)+1,IF(MONTH(D6)<10,10,IF(MONTH(D6)<12,12,14))))))>12))&"-"&TEXT(IF(AND(ISNUMBER(MATCH(MONTH(D6),{2,4,5,6,7,8,10,12},0)),DAY(D6)<=14),MONTH(D6),IF(MONTH(D6)<2,2,IF(MONTH(D6)<4,4,IF(MONTH(D6)<8,MONTH(D6)+1,IF(MONTH(D6)<10,10,IF(MONTH(D6)<12,12,14))))))-12*(IF(AND(ISNUMBER(MATCH(MONTH(D6),{2,4,5,6,7,8,10,12},0)),DAY(D6)<=14),MONTH(D6),IF(MONTH(D6)<2,2,IF(MONTH(D6)<4,4,IF(MONTH(D6)<8,MONTH(D6)+1,IF(MONTH(D6)<10,10,IF(MONTH(D6)<12,12,14))))))>12),"00"),"") -> 0 | F6: =IF(A6<>"",(MONTH(D6)-1)*2+IF(DAY(D6)<=14,1,2),0) -> 0 | G6: =IF(AND(A6<>"",N(B6)>0),INDEX(FutPrices,MATCH(E6,FutContracts,0)),0) -> 0 | H6: =IF(AND(A6<>"",N(B6)>0),INDEX(BasisByPeriod,F6),0) -> 0 | I6: =IF(AND(A6<>"",N(B6)>0),Premium,0) -> 0 | J6: =G6+H6+I6 -> 0 | K6: =HeadSold*N(B6)/100 -> 0 | L6: =N(C6)*YieldPct/100 -> 0 | M6: =K6*L6/100*J6 -> 0
D7: =IF(A7<>"",PlacementDate+A7,"") -> 0 | E7: =IF(A7<>"",(YEAR(D7)+(IF(AND(ISNUMBER(MATCH(MONTH(D7),{2,4,5,6,7,8,10,12},0)),DAY(D7)<=14),MONTH(D7),IF(MONTH(D7)<2,2,IF(MONTH(D7)<4,4,IF(MONTH(D7)<8,MONTH(D7)+1,IF(MONTH(D7)<10,10,IF(MONTH(D7)<12,12,14))))))>12))&"-"&TEXT(IF(AND(ISNUMBER(MATCH(MONTH(D7),{2,4,5,6,7,8,10,12},0)),DAY(D7)<=14),MONTH(D7),IF(MONTH(D7)<2,2,IF(MONTH(D7)<4,4,IF(MONTH(D7)<8,MONTH(D7)+1,IF(MONTH(D7)<10,10,IF(MONTH(D7)<12,12,14))))))-12*(IF(AND(ISNUMBER(MATCH(MONTH(D7),{2,4,5,6,7,8,10,12},0)),DAY(D7)<=14),MONTH(D7),IF(MONTH(D7)<2,2,IF(MONTH(D7)<4,4,IF(MONTH(D7)<8,MONTH(D7)+1,IF(MONTH(D7)<10,10,IF(MONTH(D7)<12,12,14))))))>12),"00"),"") -> 0 | F7: =IF(A7<>"",(MONTH(D7)-1)*2+IF(DAY(D7)<=14,1,2),0) -> 0 | G7: =IF(AND(A7<>"",N(B7)>0),INDEX(FutPrices,MATCH(E7,FutContracts,0)),0) -> 0 | H7: =IF(AND(A7<>"",N(B7)>0),INDEX(BasisByPeriod,F7),0) -> 0 | I7: =IF(AND(A7<>"",N(B7)>0),Premium,0) -> 0 | J7: =G7+H7+I7 -> 0 | K7: =HeadSold*N(B7)/100 -> 0 | L7: =N(C7)*YieldPct/100 -> 0 | M7: =K7*L7/100*J7 -> 0
D8: =IF(A8<>"",PlacementDate+A8,"") -> 0 | E8: =IF(A8<>"",(YEAR(D8)+(IF(AND(ISNUMBER(MATCH(MONTH(D8),{2,4,5,6,7,8,10,12},0)),DAY(D8)<=14),MONTH(D8),IF(MONTH(D8)<2,2,IF(MONTH(D8)<4,4,IF(MONTH(D8)<8,MONTH(D8)+1,IF(MONTH(D8)<10,10,IF(MONTH(D8)<12,12,14))))))>12))&"-"&TEXT(IF(AND(ISNUMBER(MATCH(MONTH(D8),{2,4,5,6,7,8,10,12},0)),DAY(D8)<=14),MONTH(D8),IF(MONTH(D8)<2,2,IF(MONTH(D8)<4,4,IF(MONTH(D8)<8,MONTH(D8)+1,IF(MONTH(D8)<10,10,IF(MONTH(D8)<12,12,14))))))-12*(IF(AND(ISNUMBER(MATCH(MONTH(D8),{2,4,5,6,7,8,10,12},0)),DAY(D8)<=14),MONTH(D8),IF(MONTH(D8)<2,2,IF(MONTH(D8)<4,4,IF(MONTH(D8)<8,MONTH(D8)+1,IF(MONTH(D8)<10,10,IF(MONTH(D8)<12,12,14))))))>12),"00"),"") -> 0 | F8: =IF(A8<>"",(MONTH(D8)-1)*2+IF(DAY(D8)<=14,1,2),0) -> 0 | G8: =IF(AND(A8<>"",N(B8)>0),INDEX(FutPrices,MATCH(E8,FutContracts,0)),0) -> 0 | H8: =IF(AND(A8<>"",N(B8)>0),INDEX(BasisByPeriod,F8),0) -> 0 | I8: =IF(AND(A8<>"",N(B8)>0),Premium,0) -> 0 | J8: =G8+H8+I8 -> 0 | K8: =HeadSold*N(B8)/100 -> 0 | L8: =N(C8)*YieldPct/100 -> 0 | M8: =K8*L8/100*J8 -> 0
D9: =IF(A9<>"",PlacementDate+A9,"") -> 0 | E9: =IF(A9<>"",(YEAR(D9)+(IF(AND(ISNUMBER(MATCH(MONTH(D9),{2,4,5,6,7,8,10,12},0)),DAY(D9)<=14),MONTH(D9),IF(MONTH(D9)<2,2,IF(MONTH(D9)<4,4,IF(MONTH(D9)<8,MONTH(D9)+1,IF(MONTH(D9)<10,10,IF(MONTH(D9)<12,12,14))))))>12))&"-"&TEXT(IF(AND(ISNUMBER(MATCH(MONTH(D9),{2,4,5,6,7,8,10,12},0)),DAY(D9)<=14),MONTH(D9),IF(MONTH(D9)<2,2,IF(MONTH(D9)<4,4,IF(MONTH(D9)<8,MONTH(D9)+1,IF(MONTH(D9)<10,10,IF(MONTH(D9)<12,12,14))))))-12*(IF(AND(ISNUMBER(MATCH(MONTH(D9),{2,4,5,6,7,8,10,12},0)),DAY(D9)<=14),MONTH(D9),IF(MONTH(D9)<2,2,IF(MONTH(D9)<4,4,IF(MONTH(D9)<8,MONTH(D9)+1,IF(MONTH(D9)<10,10,IF(MONTH(D9)<12,12,14))))))>12),"00"),"") -> 0 | F9: =IF(A9<>"",(MONTH(D9)-1)*2+IF(DAY(D9)<=14,1,2),0) -> 0 | G9: =IF(AND(A9<>"",N(B9)>0),INDEX(FutPrices,MATCH(E9,FutContracts,0)),0) -> 0 | H9: =IF(AND(A9<>"",N(B9)>0),INDEX(BasisByPeriod,F9),0) -> 0 | I9: =IF(AND(A9<>"",N(B9)>0),Premium,0) -> 0 | J9: =G9+H9+I9 -> 0 | K9: =HeadSold*N(B9)/100 -> 0 | L9: =N(C9)*YieldPct/100 -> 0 | M9: =K9*L9/100*J9 -> 0
A10: Total | B10: =SUM(B2:B9) -> 0 | K10: =SUM(K2:K9) -> 0 | M10: =SUM(M2:M9) -> 0
A12: % of marketed must total 100. Contract: days 1-14 of a contract month (Feb Apr May Jun Jul Aug Oct Dec) use that month; otherwise the next contract (ISU B2-41).

Sheet Market Data
A1: Lean hog futures curve | D1: Avg hog basis (CME Index − nearby futures)
A2: Contract | B2: $/cwt carcass | D2: Period | E2: Half-month | F2: $/cwt carcass
A3: 2026-12 | B3: 66.925 | D3: 1 | E3: Jan 1-14 | F3: 0
A4: 2027-02 | B4: 69.225 | D4: 2 | E4: Jan 15-end | F4: 0
A5: 2027-04 | B5: 74.675 | D5: 3 | E5: Feb 1-14 | F5: 0
D6: 4 | E6: Feb 15-end | F6: 0
D7: 5 | E7: Mar 1-14 | F7: 0
D8: 6 | E8: Mar 15-end | F8: 0
D9: 7 | E9: Apr 1-14 | F9: 0
D10: 8 | E10: Apr 15-end | F10: 0
D11: 9 | E11: May 1-14 | F11: 0
D12: 10 | E12: May 15-end | F12: 0
D13: 11 | E13: Jun 1-14 | F13: 0
D14: 12 | E14: Jun 15-end | F14: 0
D15: 13 | E15: Jul 1-14 | F15: 0
D16: 14 | E16: Jul 15-end | F16: 0
D17: 15 | E17: Aug 1-14 | F17: 0
... D26: 24 | E26: Dec 15-end | F26: 0

Sheet Costs
A1: Cost line | B1: Total $ | C1: $/head placed | D1: $/head sold | E1: $/cwt carcass | F1: % of total
A2: Weaned pigs | B2: =HeadPlaced*(WeanPrice+WeanFreight) -> 0 | C2: =B2/HeadPlaced -> 0 | D2: =B2/HeadSold -> 0 | E2: =B2/CarcassCwt -> 0 | F2: =B2/$B$12 -> 0
A3: Feed | B3: =FeedCost -> 0 | C3: =B3/HeadPlaced -> 0 | D3: =B3/HeadSold -> 0 | E3: =B3/CarcassCwt -> 0 | F3: =B3/$B$12 -> 0
A4: Barn / facilities | B4: =IF(BarnMode="$/space/year",HeadPlaced*BarnRent*BarnDays/365,HeadPlaced*BarnPerPig) -> 0 | C4: =B4/HeadPlaced -> 0 | D4: =B4/HeadSold -> 0 | E4: =B4/CarcassCwt -> 0 | F4: =B4/$B$12 -> 0
A5: Labor | B5: =IF(LaborMode="hours x wage",HeadPlaced*LaborHours*LaborWage,HeadPlaced*LaborPerPig) -> 0 | C5: =B5/HeadPlaced -> 0 | D5: =B5/HeadSold -> 0 | E5: =B5/CarcassCwt -> 0 | F5: =B5/$B$12 -> 0
A6: Vet / med | B6: =HeadPlaced*VetMed -> 0 | C6: =B6/HeadPlaced -> 0 | D6: =B6/HeadSold -> 0 | E6: =B6/CarcassCwt -> 0 | F6: =B6/$B$12 -> 0
A7: Utilities | B7: =HeadPlaced*Utilities -> 0 | C7: =B7/HeadPlaced -> 0 | D7: =B7/HeadSold -> 0 | E7: =B7/CarcassCwt -> 0 | F7: =B7/$B$12 -> 0
A8: Trucking to market | B8: =HeadSold*Trucking -> 0 | C8: =B8/HeadPlaced -> 0 | D8: =B8/HeadSold -> 0 | E8: =B8/CarcassCwt -> 0 | F8: =B8/$B$12 -> 0
A9: Insurance / misc | B9: =HeadPlaced*InsMisc -> 0 | C9: =B9/HeadPlaced -> 0 | D9: =B9/HeadSold -> 0 | E9: =B9/CarcassCwt -> 0 | F9: =B9/$B$12 -> 0
A10: Interest | B10: =InterestPct/100*AvgDays/365*(B2+0.5*B3) -> 0 | C10: =B10/HeadPlaced -> 0 | D10: =B10/HeadSold -> 0 | E10: =B10/CarcassCwt -> 0 | F10: =B10/$B$12 -> 0
A11: Checkoff | B11: =GrossRevenue*CheckoffPct/100 -> 0 | C11: =B11/HeadPlaced -> 0 | D11: =B11/HeadSold -> 0 | E11: =B11/CarcassCwt -> 0 | F11: =B11/$B$12 -> 0
A12: Total cost | B12: =SUM(B2:B11) -> 0 | C12: =B12/HeadPlaced -> 0 | D12: =B12/HeadSold -> 0 | E12: =B12/CarcassCwt -> 0
